2017-05-20 22:25:56.815 [error] <0.221.0> Supervisor 'Elixir.Logger.Supervisor' had child 'Elixir.Logger.ErrorHandler' started with 'Elixir.Logger.Watcher':watcher(error_logger, 'Elixir.Logger.ErrorHandler', {true,false,500}) at <0.226.0> exit with reason normal in context child_terminated
2017-05-21 19:23:36.266 [error] <0.229.0> CRASH REPORT Process <0.229.0> with 0 neighbours exited with reason: no match of right hand value {'EXIT',{undef,[{'Elixir.LogHandler',init,[[]],[]},{gen_event,server_add_handler,4,[{file,"gen_event.erl"},{line,429}]},{gen_event,handle_msg,5,[{file,"gen_event.erl"},{line,270}]},{proc_lib,init_p_do_apply,3,[{file,"proc_lib.erl"},{line,247}]}]}} in 'Elixir.LagerUnit.Application':start/2 line 15 in application_master:init/4 line 134
2017-05-21 19:24:18.128 [error] <0.193.0> CRASH REPORT Process <0.193.0> with 0 neighbours exited with reason: no match of right hand value {'EXIT',{undef,[{'Elixir.LogHandler',init,[[]],[]},{gen_event,server_add_handler,4,[{file,"gen_event.erl"},{line,429}]},{gen_event,handle_msg,5,[{file,"gen_event.erl"},{line,270}]},{proc_lib,init_p_do_apply,3,[{file,"proc_lib.erl"},{line,247}]}]}} in 'Elixir.LagerUnit.Application':start/2 line 14 in application_master:init/4 line 134
2017-05-21 19:24:37.293 [error] <0.193.0> CRASH REPORT Process <0.193.0> with 0 neighbours exited with reason: no match of right hand value ok in 'Elixir.LagerUnit.Application':start/2 line 15 in application_master:init/4 line 134
2017-05-21 19:28:38.680 [error] <0.174.0> gen_event 'Elixir.LagerUnit.LogHandler' installed in lager_event terminated with reason: #{'__exception__' => true,'__struct__' => 'Elixir.Protocol.UndefinedError',description => <<>>,protocol => 'Elixir.String.Chars',value => {log,{lager_msg,[],[{pid,<0.31.0>}],info,{["2017",45,"05",45,"21"],["19",58,"28",58,"38",46,"666"]},{1495,420118,666032},[65,112,112,108,105,99,97,116,105,111,110,32,"exlager_unit",32,115,116,97,114,116,101,100,32,111,110,32,110,111,100,101,32,"nonode@nohost"]}}} in 'Elixir.String.Chars':'impl_for!'/1 line 3
2017-05-21 19:39:55.198 [error] <0.180.0> gen_event 'Elixir.LagerUnit.LogHandler' installed in lager_event terminated with reason: {'module could not be loaded',[{'Elixir.LogCapturer',capture,[<<"Application exlager_unit started on node nonode@nohost">>],[]},{'Elixir.LagerUnit.LogHandler',handle_event,2,[{file,"lib/exlager_unit/log_handler.ex"},{line,9}]},{gen_event,server_update,4,[{file,"gen_event.erl"},{line,533}]},{gen_event,server_notify,4,[{file,"gen_event.erl"},{line,515}]},{gen_event,handle_msg,5,[{file,"gen_event.erl"},{line,256}]},{proc_lib,init_p_do_apply,3,[{file,"proc_lib.erl"},{line,247}]}]}
2017-05-21 19:42:40.546 [error] <0.164.0> gen_event 'Elixir.LagerUnit.LogHandler' installed in lager_event terminated with reason: {'module could not be loaded',[{'Elixir.LogCapturer',capture,[<<"Application exlager_unit started on node nonode@nohost">>],[]},{'Elixir.LagerUnit.LogHandler',handle_event,2,[{file,"lib/exlager_unit/log_handler.ex"},{line,9}]},{gen_event,server_update,4,[{file,"gen_event.erl"},{line,533}]},{gen_event,server_notify,4,[{file,"gen_event.erl"},{line,515}]},{gen_event,handle_msg,5,[{file,"gen_event.erl"},{line,256}]},{proc_lib,init_p_do_apply,3,[{file,"proc_lib.erl"},{line,247}]}]}
2017-05-21 19:45:44.998 [error] <0.174.0> gen_event 'Elixir.LagerUnit.LogHandler' installed in lager_event terminated with reason: {'module could not be loaded',[{'Elixir.LogCapturer',capture,[<<"Application exlager_unit started on node nonode@nohost">>],[]},{'Elixir.LagerUnit.LogHandler',handle_event,2,[{file,"lib/exlager_unit/log_handler.ex"},{line,9}]},{gen_event,server_update,4,[{file,"gen_event.erl"},{line,533}]},{gen_event,server_notify,4,[{file,"gen_event.erl"},{line,515}]},{gen_event,handle_msg,5,[{file,"gen_event.erl"},{line,256}]},{proc_lib,init_p_do_apply,3,[{file,"proc_lib.erl"},{line,247}]}]}
2017-05-21 19:46:51.002 [error] <0.196.0> gen_server 'Elixir.LagerUnit.LogCapturer' terminated with reason: bad return value: {ok,#{}}
2017-05-21 19:46:51.002 [error] <0.196.0> CRASH REPORT Process 'Elixir.LagerUnit.LogCapturer' with 0 neighbours exited with reason: bad return value: {ok,#{}} in gen_server:terminate/7 line 812
2017-05-21 19:46:51.038 [error] <0.195.0> Supervisor 'Elixir.LagerUnit.Supervisor' had child 'Elixir.LagerUnit.LogCapturer' started with 'Elixir.LagerUnit.LogCapturer':start_link() at <0.196.0> exit with reason bad return value: {ok,#{}} in context child_terminated
2017-05-21 19:46:51.038 [error] <0.200.0> gen_server 'Elixir.LagerUnit.LogCapturer' terminated with reason: bad return value: {ok,#{}}
2017-05-21 19:46:51.038 [error] <0.200.0> CRASH REPORT Process 'Elixir.LagerUnit.LogCapturer' with 0 neighbours exited with reason: bad return value: {ok,#{}} in gen_server:terminate/7 line 812
2017-05-21 19:46:51.038 [error] <0.195.0> Supervisor 'Elixir.LagerUnit.Supervisor' had child 'Elixir.LagerUnit.LogCapturer' started with 'Elixir.LagerUnit.LogCapturer':start_link() at <0.200.0> exit with reason bad return value: {ok,#{}} in context child_terminated
2017-05-21 19:46:51.038 [error] <0.201.0> gen_server 'Elixir.LagerUnit.LogCapturer' terminated with reason: bad return value: {ok,#{}}
2017-05-21 19:46:51.038 [error] <0.201.0> CRASH REPORT Process 'Elixir.LagerUnit.LogCapturer' with 0 neighbours exited with reason: bad return value: {ok,#{}} in gen_server:terminate/7 line 812
2017-05-21 19:46:51.038 [error] <0.195.0> Supervisor 'Elixir.LagerUnit.Supervisor' had child 'Elixir.LagerUnit.LogCapturer' started with 'Elixir.LagerUnit.LogCapturer':start_link() at <0.201.0> exit with reason bad return value: {ok,#{}} in context child_terminated
2017-05-21 19:46:51.045 [error] <0.203.0> gen_server 'Elixir.LagerUnit.LogCapturer' terminated with reason: bad return value: {ok,#{}}
2017-05-21 19:46:51.045 [error] <0.203.0> CRASH REPORT Process 'Elixir.LagerUnit.LogCapturer' with 0 neighbours exited with reason: bad return value: {ok,#{}} in gen_server:terminate/7 line 812
2017-05-21 19:46:51.046 [error] <0.195.0> Supervisor 'Elixir.LagerUnit.Supervisor' had child 'Elixir.LagerUnit.LogCapturer' started with 'Elixir.LagerUnit.LogCapturer':start_link() at <0.203.0> exit with reason bad return value: {ok,#{}} in context child_terminated
2017-05-21 19:46:51.046 [error] <0.195.0> Supervisor 'Elixir.LagerUnit.Supervisor' had child 'Elixir.LagerUnit.LogCapturer' started with 'Elixir.LagerUnit.LogCapturer':start_link() at <0.203.0> exit with reason reached_max_restart_intensity in context shutdown
2017-05-21 19:48:27.971 [error] <0.186.0> gen_server 'Elixir.LagerUnit.LogCapturer' terminated with reason: bad return value: {ok,#{}}
2017-05-21 19:48:27.971 [error] <0.186.0> CRASH REPORT Process 'Elixir.LagerUnit.LogCapturer' with 0 neighbours exited with reason: bad return value: {ok,#{}} in gen_server:terminate/7 line 812
2017-05-21 19:48:28.014 [error] <0.185.0> Supervisor 'Elixir.LagerUnit.Supervisor' had child 'Elixir.LagerUnit.LogCapturer' started with 'Elixir.LagerUnit.LogCapturer':start_link() at <0.186.0> exit with reason bad return value: {ok,#{}} in context child_terminated
2017-05-21 19:48:28.014 [error] <0.190.0> gen_server 'Elixir.LagerUnit.LogCapturer' terminated with reason: bad return value: {ok,#{}}
2017-05-21 19:48:28.014 [error] <0.190.0> CRASH REPORT Process 'Elixir.LagerUnit.LogCapturer' with 0 neighbours exited with reason: bad return value: {ok,#{}} in gen_server:terminate/7 line 812
2017-05-21 19:48:28.014 [error] <0.185.0> Supervisor 'Elixir.LagerUnit.Supervisor' had child 'Elixir.LagerUnit.LogCapturer' started with 'Elixir.LagerUnit.LogCapturer':start_link() at <0.190.0> exit with reason bad return value: {ok,#{}} in context child_terminated
2017-05-21 19:48:28.019 [error] <0.191.0> gen_server 'Elixir.LagerUnit.LogCapturer' terminated with reason: bad return value: {ok,#{}}
2017-05-21 19:48:28.020 [error] <0.191.0> CRASH REPORT Process 'Elixir.LagerUnit.LogCapturer' with 0 neighbours exited with reason: bad return value: {ok,#{}} in gen_server:terminate/7 line 812
2017-05-21 19:48:28.020 [error] <0.185.0> Supervisor 'Elixir.LagerUnit.Supervisor' had child 'Elixir.LagerUnit.LogCapturer' started with 'Elixir.LagerUnit.LogCapturer':start_link() at <0.191.0> exit with reason bad return value: {ok,#{}} in context child_terminated
2017-05-21 19:48:28.028 [error] <0.192.0> gen_server 'Elixir.LagerUnit.LogCapturer' terminated with reason: bad return value: {ok,#{}}
2017-05-21 19:48:28.029 [error] <0.192.0> CRASH REPORT Process 'Elixir.LagerUnit.LogCapturer' with 0 neighbours exited with reason: bad return value: {ok,#{}} in gen_server:terminate/7 line 812
2017-05-21 19:48:28.029 [error] <0.185.0> Supervisor 'Elixir.LagerUnit.Supervisor' had child 'Elixir.LagerUnit.LogCapturer' started with 'Elixir.LagerUnit.LogCapturer':start_link() at <0.192.0> exit with reason bad return value: {ok,#{}} in context child_terminated
2017-05-21 19:48:28.029 [error] <0.185.0> Supervisor 'Elixir.LagerUnit.Supervisor' had child 'Elixir.LagerUnit.LogCapturer' started with 'Elixir.LagerUnit.LogCapturer':start_link() at <0.192.0> exit with reason reached_max_restart_intensity in context shutdown
2017-05-22 06:45:19.150 [error] <0.196.0> gen_server 'Elixir.LagerUnit.LogCapturer' terminated with reason: #{'__exception__' => true,'__struct__' => 'Elixir.RuntimeError',message => <<"attempted to call GenServer LagerUnit.LogCapturer but no handle_call/3 clause was provided">>} in 'Elixir.LagerUnit.LogCapturer':handle_call/3 line 559
2017-05-22 06:45:19.151 [error] <0.196.0> CRASH REPORT Process 'Elixir.LagerUnit.LogCapturer' with 0 neighbours exited with reason: #{'__exception__' => true,'__struct__' => 'Elixir.RuntimeError',message => <<"attempted to call GenServer LagerUnit.LogCapturer but no handle_call/3 clause was provided">>} in 'Elixir.LagerUnit.LogCapturer':handle_call/3 line 559 in gen_server:terminate/7 line 812
2017-05-22 06:45:19.151 [error] <0.195.0> Supervisor 'Elixir.LagerUnit.Supervisor' had child 'Elixir.LagerUnit.LogCapturer' started with 'Elixir.LagerUnit.LogCapturer':start_link() at <0.196.0> exit with reason #{'__exception__' => true,'__struct__' => 'Elixir.RuntimeError',message => <<"attempted to call GenServer LagerUnit.LogCapturer but no handle_call/3 clause was provided">>} in 'Elixir.LagerUnit.LogCapturer':handle_call/3 line 559 in context child_terminated
2017-05-22 06:46:51.434 [error] <0.196.0> gen_server 'Elixir.LagerUnit.LogCapturer' terminated with reason: #{'__exception__' => true,'__struct__' => 'Elixir.RuntimeError',message => <<"attempted to call GenServer LagerUnit.LogCapturer but no handle_call/3 clause was provided">>} in 'Elixir.LagerUnit.LogCapturer':handle_call/3 line 559
2017-05-22 06:46:51.435 [error] <0.196.0> CRASH REPORT Process 'Elixir.LagerUnit.LogCapturer' with 0 neighbours exited with reason: #{'__exception__' => true,'__struct__' => 'Elixir.RuntimeError',message => <<"attempted to call GenServer LagerUnit.LogCapturer but no handle_call/3 clause was provided">>} in 'Elixir.LagerUnit.LogCapturer':handle_call/3 line 559 in gen_server:terminate/7 line 812
2017-05-22 06:46:51.435 [error] <0.195.0> Supervisor 'Elixir.LagerUnit.Supervisor' had child 'Elixir.LagerUnit.LogCapturer' started with 'Elixir.LagerUnit.LogCapturer':start_link() at <0.196.0> exit with reason #{'__exception__' => true,'__struct__' => 'Elixir.RuntimeError',message => <<"attempted to call GenServer LagerUnit.LogCapturer but no handle_call/3 clause was provided">>} in 'Elixir.LagerUnit.LogCapturer':handle_call/3 line 559 in context child_terminated
